<?xml version="1.0" encoding="UTF-8"?>
<testsuites>
	<testsuite errors="0" failures="1" file="tests.py" name="tests.PostTestCase-20200217063211" skipped="0" tests="10" time="0.023" timestamp="2020-02-17T06:32:11">
		<testcase classname="tests.PostTestCase" file="module3/tests.py" line="235" name="test_task10_make_migrations" time="0.010" timestamp="2020-02-17T06:32:11">
			<system-out>
<![CDATA[]]>			</system-out>
			<system-err>
<![CDATA[]]>			</system-err>
		</testcase>
		<testcase classname="tests.PostTestCase" file="module3/tests.py" line="111" name="test_task1_post_model_exists" time="0.001" timestamp="2020-02-17T06:32:11">
			<system-out>
<![CDATA[]]>			</system-out>
			<system-err>
<![CDATA[]]>			</system-err>
		</testcase>
		<testcase classname="tests.PostTestCase" file="module3/tests.py" line="120" name="test_task2_author_exists" time="0.001" timestamp="2020-02-17T06:32:11">
			<system-out>
<![CDATA[]]>			</system-out>
			<system-err>
<![CDATA[]]>			</system-err>
		</testcase>
		<testcase classname="tests.PostTestCase" file="module3/tests.py" line="133" name="test_task3_body_exists" time="0.001" timestamp="2020-02-17T06:32:11">
			<system-out>
<![CDATA[]]>			</system-out>
			<system-err>
<![CDATA[]]>			</system-err>
		</testcase>
		<testcase classname="tests.PostTestCase" file="module3/tests.py" line="139" name="test_task4_postdate_exists" time="0.001" timestamp="2020-02-17T06:32:11">
			<system-out>
<![CDATA[]]>			</system-out>
			<system-err>
<![CDATA[]]>			</system-err>
		</testcase>
		<testcase classname="tests.PostTestCase" file="module3/tests.py" line="145" name="test_task5_str_exists" time="0.001" timestamp="2020-02-17T06:32:11">
			<system-out>
<![CDATA[]]>			</system-out>
			<system-err>
<![CDATA[]]>			</system-err>
		</testcase>
		<testcase classname="tests.PostTestCase" file="module3/tests.py" line="148" name="test_task6_get_abs_url_exists" time="0.000" timestamp="2020-02-17T06:32:11">
			<system-out>
<![CDATA[]]>			</system-out>
			<system-err>
<![CDATA[]]>			</system-err>
		</testcase>
		<testcase classname="tests.PostTestCase" file="module3/tests.py" line="151" name="test_task7_register_model_in_admin" time="0.002" timestamp="2020-02-17T06:32:11">
			<system-out>
<![CDATA[]]>			</system-out>
			<system-err>
<![CDATA[]]>			</system-err>
		</testcase>
		<testcase classname="tests.PostTestCase" file="module3/tests.py" line="173" name="test_task8_update_views_with_BlogPost" time="0.003" timestamp="2020-02-17T06:32:11">
			<system-out>
<![CDATA[]]>			</system-out>
			<system-err>
<![CDATA[]]>			</system-err>
		</testcase>
		<testcase classname="tests.PostTestCase" file="module3/tests.py" line="208" name="test_task9_update_post_view_with_BlogPost" time="0.003" timestamp="2020-02-17T06:32:11">
			<failure message="Did you set `post` equal to `get_object_or_404`?" type="AssertionError">
<![CDATA[Traceback (most recent call last):
  File "/home/m7885709/django/python-django-models-authentication/module3/tests.py", line 232, in test_task9_update_post_view_with_BlogPost
    self.assertTrue(set_posts_found, msg="Did you set `post` equal to `get_object_or_404`?")
  File "/home/m7885709/django/python-django-models-authentication/support/SimplerTestCase.py", line 12, in assertTrue
    self.fail(msg or (str(expr) + "is not True"))
AssertionError: Did you set `post` equal to `get_object_or_404`?
]]>			</failure>
			<system-out>
<![CDATA[]]>			</system-out>
			<system-err>
<![CDATA[]]>			</system-err>
		</testcase>
	</testsuite>
</testsuites>
